Workbook

Sheet Bbdd
A1: fecha_creacion_transaccion | B1: ID TRANSACCION | C1: Aliado | D1: Numero_de_Matricula | E1: Orden_Matricula | F1: cedula_cliente | G1: Nombre_cliente | H1: ID Estudiante | I1: Periodo | J1: CC | K1: Tipo de estudiante | L1: Programa | M1: Nivel | N1: Operador | O1: Área | P1: Operación | Q1: Cate | R1: Subcate | S1: Cohorte | T1: cc | U1: =_xlfn.XLOOKUP(B1,[1]Hoja1!$B:$B,[1]Hoja1!$U:$U) -> Lider | V1: Area | W1: PUNTOS | X1: Asesor
A2: 45971.53 | B2: 20103787 | C2: ROMBO V2 | D2: 55808 | E2: OMC | F2: 1233510311 | G2: Nestor Armando Quiroga Silva | H2: 100081970 | I2: 202604 | J2: 1233510311 | K2: OPCION DE GRADO | L2: DIP OPC GRA ANA DAT PYTHON VIR | M2: EDUCACION CONTINUA | N2: CEI_BOGOTA | O2: Estudiante Nuevo | P2: Contact | Q2: Sello Financiero | R2: Tiene Sello Financiero (Aprobado Directo) | S2: Cohorte 1 | T2: 52834109 | U2: JAVIER ORLANDO HERNANDEZ RIVERA | V2: OP GRADO - INGLÉS | W2: =IF(V2="pregrado",31, IF(V2="posgrados",31, IF(V2="rEINTEGROS",7, IF(V2="BIT",90, IF(V2="OP GRADO - INGLÉS",17,""))))) -> 17 | X2: Jeny Marlen Ordoñez Mendez
A3: 45975.672 | B3: 20104183 | C3: ROMBO V2 | D3: 55952 | E3: OMC | F3: 1121857096 | G3: Yerly Marcela Caicedo Garzon | H3: 100205569 | I3: 202604 | J3: 1121857096 | K3: OPCION DE GRADO | L3: SEM EVAL NEUP Y ESTR INTERV ED | M3: EDUCACION CONTINUA | N3: CEI_BOGOTA | O3: Estudiante Nuevo | P3: Contact | Q3: Sello Financiero | R3: Tiene Sello Financiero (Aprobado Directo) | S3: Cohorte 1 | T3: 52834109 | U3: JAVIER ORLANDO HERNANDEZ RIVERA | V3: OP GRADO - INGLÉS | W3: =IF(V3="pregrado",31, IF(V3="posgrados",31, IF(V3="rEINTEGROS",7, IF(V3="BIT",90, IF(V3="OP GRADO - INGLÉS",17,""))))) -> 17 | X3: Jeny Marlen Ordoñez Mendez
A4: 45973.521 | B4: 20103973 | C4: ROMBO V2 | D4: 55957 | E4: OMC | F4: 1007243941 | G4: Alejandra Morales Barbosa barbosa | H4: 100127159 | I4: 202604 | J4: 1007243941 | K4: OPCION DE GRADO | L4: CURSO MOD DE GRADO CALIDAD VIR | M4: EDUCACION CONTINUA | N4: CEI_BOGOTA | O4: Estudiante Nuevo | P4: Contact | Q4: Sello Financiero | R4: Tiene Sello Financiero (Aprobado Directo) | S4: Cohorte 1 | T4: 1033714104 | U4: JAVIER ORLANDO HERNANDEZ RIVERA | V4: OP GRADO - INGLÉS | W4: =IF(V4="pregrado",31, IF(V4="posgrados",31, IF(V4="rEINTEGROS",7, IF(V4="BIT",90, IF(V4="OP GRADO - INGLÉS",17,""))))) -> 17 | X4: Ruben Darío Elles Trujillo
A5: 45974.493 | B5: 20104055 | C5: ROMBO V2 | D5: 55970 | E5: OMC | F5: 1144138713 | G5: Yefferson Yefferson Santos Ortiz | H5: 100222490 | I5: 202604 | J5: 1144138713 | K5: OPCION DE GRADO | L5: SEM INTEL NEG CON POWER BI VIR | M5: EDUCACION CONTINUA | N5: CEI_BOGOTA | O5: Estudiante Nuevo | P5: Contact | Q5: Sello Financiero | R5: Tiene Sello Financiero (Aprobado Directo) | S5: Cohorte 1 | T5: 1033714104 | U5: JAVIER ORLANDO HERNANDEZ RIVERA | V5: OP GRADO - INGLÉS | W5: =IF(V5="pregrado",31, IF(V5="posgrados",31, IF(V5="rEINTEGROS",7, IF(V5="BIT",90, IF(V5="OP GRADO - INGLÉS",17,""))))) -> 17 | X5: Ruben Darío Elles Trujillo
A6: 45979.547 | B6: 20104300 | C6: ROMBO V2 | D6: 56846 | E6: OMC | F6: 1000941707 | G6: Leidy Camila Ballen Aldana | H6: 100136725 | I6: 202604 | J6: 1000941707 | K6: OPCION DE GRADO | L6: CUR MOD GRA ESP MARK DIGIT VIR | M6: EDUCACION CONTINUA | N6: CEI_BOGOTA | O6: Estudiante Nuevo | P6: Contact | Q6: Sello Financiero | R6: Tiene Sello Financiero (Aprobado Directo) | S6: Cohorte 1 | T6: 1033714104 | U6: JAVIER ORLANDO HERNANDEZ RIVERA | V6: OP GRADO - INGLÉS | W6: =IF(V6="pregrado",31, IF(V6="posgrados",31, IF(V6="rEINTEGROS",7, IF(V6="BIT",90, IF(V6="OP GRADO - INGLÉS",17,""))))) -> 17 | X6: Ruben Darío Elles Trujillo
A7: 45979.671 | B7: 20104320 | C7: ROMBO V2 | D7: 56893 | E7: OMC | F7: 1106395487 | G7: Jennifer Katerine Medina Cardenas | H7: 100160050 | I7: 202604 | J7: 1106395487 | K7: OPCION DE GRADO | L7: DIP SEG Y SALUD TRA RIES P VIR | M7: EDUCACION CONTINUA | N7: CEI_BOGOTA | O7: Estudiante Nuevo | P7: Contact | Q7: Sello Financiero | R7: Tiene Sello Financiero (Aprobado Directo) | S7: Cohorte 1 | T7: 1033714104 | U7: JAVIER ORLANDO HERNANDEZ RIVERA | V7: OP GRADO - INGLÉS | W7: =IF(V7="pregrado",31, IF(V7="posgrados",31, IF(V7="rEINTEGROS",7, IF(V7="BIT",90, IF(V7="OP GRADO - INGLÉS",17,""))))) -> 17 | X7: Ruben Darío Elles Trujillo
A8: 45987.731 | B8: 20105010 | C8: ROMBO V2 | D8: 56896 | E8: OMC | F8: 1117322557 | G8: Erika Erika Guarin Garcia | H8: 100188082 | I8: 202604 | J8: 1117322557 | K8: OPCION DE GRADO | L8: DIP SEG LOG CIO INTER BASC VIR | M8: EDUCACION CONTINUA | N8: CEI_BOGOTA | O8: Estudiante Nuevo | P8: Contact | Q8: Sello Financiero | R8: Tiene Sello Financiero (Aprobado Directo) | S8: Cohorte 1 | T8: 60345453 | U8: JAVIER ORLANDO HERNANDEZ RIVERA | V8: OP GRADO - INGLÉS | W8: =IF(V8="pregrado",31, IF(V8="posgrados",31, IF(V8="rEINTEGROS",7, IF(V8="BIT",90, IF(V8="OP GRADO - INGLÉS",17,""))))) -> 17 | X8: Claudia Restrepo Gonzalez
A9: 45981.431 | B9: 20104474 | C9: ROMBO V2 | D9: 56904 | E9: OMC | F9: 1000378303 | G9: Geraldine Geraldine Estrada Vanegas | H9: 100176157 | I9: 202604 | J9: 1000378303 | K9: OPCION DE GRADO | L9: DIP SEG Y SALUD TRA RIES P VIR | M9: EDUCACION CONTINUA | N9: CEI_BOGOTA | O9: Estudiante Nuevo | P9: Contact | Q9: Sello Financiero | R9: Tiene Sello Financiero (Aprobado Directo) | S9: Cohorte 1 | T9: 52834109 | U9: JAVIER ORLANDO HERNANDEZ RIVERA | V9: OP GRADO - INGLÉS | W9: =IF(V9="pregrado",31, IF(V9="posgrados",31, IF(V9="rEINTEGROS",7, IF(V9="BIT",90, IF(V9="OP GRADO - INGLÉS",17,""))))) -> 17 | X9: Jeny Marlen Ordoñez Mendez
A10: 45985.588 | B10: 20104695 | C10: ROMBO V2 | D10: 56907 | E10: OMC | F10: 1141114543 | G10: ISABELA ROJAS SALCEDO | H10: 100111162 | I10: 202604 | J10: 52005401 | K10: OPCION DE GRADO | L10: DIP SEG Y SALUD TRA RIES P VIR | M10: EDUCACION CONTINUA | N10: CEI_BOGOTA | O10: Estudiante Nuevo | P10: Contact | Q10: Sello Financiero | R10: Tiene Sello Financiero (Aprobado Directo) | S10: Cohorte 1 | T10: 52834109 | U10: JAVIER ORLANDO HERNANDEZ RIVERA | V10: OP GRADO - INGLÉS | W10: =IF(V10="pregrado",31, IF(V10="posgrados",31, IF(V10="rEINTEGROS",7, IF(V10="BIT",90, IF(V10="OP GRADO - INGLÉS",17,""))))) -> 17 | X10: Jeny Marlen Ordoñez Mendez
A11: 45986.638 | B11: 20104823 | C11: ROMBO V2 | D11: 56951 | E11: OMC | F11: 1016005858 | G11: Nicole Ariana Ospina Godoy | H11: 100109607 | I11: 202604 | J11: 1016005858 | K11: OPCION DE GRADO | L11: DIP SEG LOG CIO INTER BASC VIR | M11: EDUCACION CONTINUA | N11: CEI_BOGOTA | O11: Estudiante Nuevo | P11: Contact | Q11: Sello Financiero | R11: Tiene Sello Financiero (Aprobado Directo) | S11: Cohorte 1 | T11: 1033714104 | U11: JAVIER ORLANDO HERNANDEZ RIVERA | V11: OP GRADO - INGLÉS | W11: =IF(V11="pregrado",31, IF(V11="posgrados",31, IF(V11="rEINTEGROS",7, IF(V11="BIT",90, IF(V11="OP GRADO - INGLÉS",17,""))))) -> 17 | X11: Ruben Darío Elles Trujillo
A12: 45985.522 | B12: 20104685 | C12: ROMBO V2 | D12: 56971 | E12: OMC | F12: 1001506092 | G12: Mateo Mateo Bermudez Rios | H12: 100145617 | I12: 202604 | J12: 1001506092 | K12: OPCION DE GRADO | L12: DIPLOMADO TELEPSICOLOGIA VIR | M12: EDUCACION CONTINUA | N12: CEI_BOGOTA | O12: Estudiante Nuevo | P12: Contact | Q12: Sello Financiero | R12: Tiene Sello Financiero (Aprobado Directo) | S12: Cohorte 1 | T12: 1033714104 | U12: JAVIER ORLANDO HERNANDEZ RIVERA | V12: OP GRADO - INGLÉS | W12: =IF(V12="pregrado",31, IF(V12="posgrados",31, IF(V12="rEINTEGROS",7, IF(V12="BIT",90, IF(V12="OP GRADO - INGLÉS",17,""))))) -> 17 | X12: Ruben Darío Elles Trujillo
A13: 45986.382 | B13: 20104761 | C13: ROMBO V2 | D13: 56972 | E13: OMC | F13: 1078180069 | G13: Cenives Patricia Maturana Renteria | H13: 100201123 | I13: 202604 | J13: 1078180069 | K13: OPCION DE GRADO | L13: SEM PROF EVAL CUL INCLU Y PRAC | M13: EDUCACION CONTINUA | N13: CEI_BOGOTA | O13: Estudiante Nuevo | P13: Contact | Q13: Sello Financiero | R13: Tiene Sello Financiero (Aprobado Directo) | S13: Cohorte 1 | T13: 1033714104 | U13: JAVIER ORLANDO HERNANDEZ RIVERA | V13: OP GRADO - INGLÉS | W13: =IF(V13="pregrado",31, IF(V13="posgrados",31, IF(V13="rEINTEGROS",7, IF(V13="BIT",90, IF(V13="OP GRADO - INGLÉS",17,""))))) -> 17 | X13: Ruben Darío Elles Trujillo
... A39: 46008.526 | B39: 20108180 | C39: ROMBO V2 | D39: 57495 | E39: OMC | F39: 1073524528 | G39: Jessica Lorena Rincon Riveros | H39: 100104462 | I39: 202604 | J39: 1073524528 | K39: OPCION DE GRADO | L39: DIP SEG Y SALUD TRA RIES P VIR | M39: EDUCACION CONTINUA | N39: CEI_BOGOTA | O39: Estudiante Nuevo | P39: Contact | Q39: Sello Financiero | R39: Tiene Sello Financiero (Aprobado Directo) | S39: Cohorte 1 | T39: 52834109 | U39: JAVIER ORLANDO HERNANDEZ RIVERA | V39: OP GRADO - INGLÉS | W39: =IF(V39="pregrado",31, IF(V39="posgrados",31, IF(V39="rEINTEGROS",7, IF(V39="BIT",90, IF(V39="OP GRADO - INGLÉS",17,""))))) -> 17 | X39: Jeny Marlen Ordoñez Mendez
A40: 46073.695 | B40: 20125364 | C40: ROMBO V2 | D40: 57532 | E40: OMC | F40: 1012454021 | G40: Yeison Arturo Pestana Martinez martinez | H40: 100125393 | I40: 202604 | J40: 1012454021 | K40: OPCION DE GRADO | L40: CURSO MOD GRADO GERE SEGUR VIR | M40: EDUCACION CONTINUA | N40: 0 | O40: Estudiante Nuevo | P40: Contact | Q40: Sello Financiero | R40: Tiene Sello Financiero (Aprobado Directo) | S40: Cohorte 1 | T40: 1033714104 | U40: JAVIER ORLANDO HERNANDEZ RIVERA | V40: OP GRADO - INGLÉS | W40: =IF(V40="pregrado",31, IF(V40="posgrados",31, IF(V40="rEINTEGROS",7, IF(V40="BIT",90, IF(V40="OP GRADO - INGLÉS",17,""))))) -> 17 | X40: Ruben Darío Elles Trujillo
A41: 46076.71 | B41: 20125787 | C41: ROMBO V2 | D41: 57541 | E41: OMC | F41: 43536188 | G41: Gloria Maria Montoya Ospina | H41: 100130458 | I41: 202604 | J41: 1036634440 | K41: OPCION DE GRADO | L41: CUR MOD GR ESP AUDIT SALUD VIR | M41: EDUCACION CONTINUA | N41: CEI_BOGOTA | O41: Estudiante Nuevo | P41: Contact | Q41: Sello Financiero | R41: Tiene Sello Financiero (Aprobado Directo) | S41: Cohorte 1 | T41: 52834109 | U41: JAVIER ORLANDO HERNANDEZ RIVERA | V41: OP GRADO - INGLÉS | W41: =IF(V41="pregrado",31, IF(V41="posgrados",31, IF(V41="rEINTEGROS",7, IF(V41="BIT",90, IF(V41="OP GRADO - INGLÉS",17,""))))) -> 17 | X41: Jeny Marlen Ordoñez Mendez
A42: 46008.417 | B42: 20108111 | C42: ROMBO V2 | D42: 57548 | E42: OMC | F42: 1116790540 | G42: MARIA JULIANA MOJICA FIGUERA | H42: 100132605 | I42: 202604 | J42: 1116792540 | K42: OPCION DE GRADO | L42: DIP SEG Y SALUD TRA RIES P VIR | M42: EDUCACION CONTINUA | N42: CEI_BOGOTA | O42: Estudiante Nuevo | P42: Contact | Q42: Sello Financiero | R42: Tiene Sello Financiero (Aprobado Directo) | S42: Cohorte 1 | T42: 1033714104 | U42: JAVIER ORLANDO HERNANDEZ RIVERA | V42: OP GRADO - INGLÉS | W42: =IF(V42="pregrado",31, IF(V42="posgrados",31, IF(V42="rEINTEGROS",7, IF(V42="BIT",90, IF(V42="OP GRADO - INGLÉS",17,""))))) -> 17 | X42: Ruben Darío Elles Trujillo
A43: 46043.625 | B43: 20115817 | C43: ROMBO V2 | D43: 57550 | E43: OMC | F43: 1082986121 | G43: yeidis delcarmen Escobar Bertel | H43: 100133748 | I43: 202604 | J43: 1082892748 | K43: OPCION DE GRADO | L43: DIP SEG LOG CIO INTER BASC VIR | M43: EDUCACION CONTINUA | N43: CEI_BOGOTA | O43: Estudiante Nuevo | P43: Contact | Q43: Sello Financiero | R43: Tiene Sello Financiero (Aprobado Directo) | S43: Cohorte 1 | T43: 52834109 | U43: JAVIER ORLANDO HERNANDEZ RIVERA | V43: OP GRADO - INGLÉS | W43: =IF(V43="pregrado",31, IF(V43="posgrados",31, IF(V43="rEINTEGROS",7, IF(V43="BIT",90, IF(V43="OP GRADO - INGLÉS",17,""))))) -> 17 | X43: Jeny Marlen Ordoñez Mendez
A44: 46035.435 | B44: 20112460 | C44: ROMBO V2 | D44: 57551 | E44: OMC | F44: 1214714142 | G44: Yeraldine Yeraldine Vargas Galeano | H44: 100134191 | I44: 202604 | J44: 1214714142 | K44: OPCION DE GRADO | L44: DIP SEG Y SALUD TRA RIES P VIR | M44: EDUCACION CONTINUA | N44: CEI_BOGOTA | O44: Estudiante Nuevo | P44: Contact | Q44: Sello Financiero | R44: Tiene Sello Financiero (Aprobado Directo) | S44: Cohorte 1 | T44: 52834109 | U44: JAVIER ORLANDO HERNANDEZ RIVERA | V44: OP GRADO - INGLÉS | W44: =IF(V44="pregrado",31, IF(V44="posgrados",31, IF(V44="rEINTEGROS",7, IF(V44="BIT",90, IF(V44="OP GRADO - INGLÉS",17,""))))) -> 17 | X44: Jeny Marlen Ordoñez Mendez
A45: 46006.733 | B45: 20107555 | C45: ROMBO V2 | D45: 57552 | E45: OMC | F45: 1106783921 | G45: TATIANA PEREZ RIAÑO | H45: 100134427 | I45: 202604 | J45: 1117826388 | K45: OPCION DE GRADO | L45: CUR MOD GR ESP AUDIT SALUD VIR | M45: EDUCACION CONTINUA | N45: CEI_BOGOTA | O45: Estudiante Nuevo | P45: Contact | Q45: Sello Financiero | R45: Tiene Sello Financiero (Aprobado Directo) | S45: Cohorte 1 | T45: 60345453 | U45: JAVIER ORLANDO HERNANDEZ RIVERA | V45: OP GRADO - INGLÉS | W45: =IF(V45="pregrado",31, IF(V45="posgrados",31, IF(V45="rEINTEGROS",7, IF(V45="BIT",90, IF(V45="OP GRADO - INGLÉS",17,""))))) -> 17 | X45: Claudia Restrepo Gonzalez
A46: 46071.392 | B46: 20124352 | C46: ROMBO V2 | D46: 57562 | E46: OMC | F46: 1003828711 | G46: Johan Sebastian Zambrano Polanco | H46: 100141030 | I46: 202604 | J46: 1003828711 | K46: OPCION DE GRADO | L46: SEM INTEL NEG CON POWER BI VIR | M46: EDUCACION CONTINUA | N46: CEI_BOGOTA | O46: Estudiante Nuevo | P46: Contact | Q46: Sello Financiero | R46: Tiene Sello Financiero (Aprobado Directo) | S46: Cohorte 1 | T46: 52834109 | U46: JAVIER ORLANDO HERNANDEZ RIVERA | V46: OP GRADO - INGLÉS | W46: =IF(V46="pregrado",31, IF(V46="posgrados",31, IF(V46="rEINTEGROS",7, IF(V46="BIT",90, IF(V46="OP GRADO - INGLÉS",17,""))))) -> 17 | X46: Jeny Marlen Ordoñez Mendez
A47: 46039.466 | B47: 20114686 | C47: ROMBO V2 | D47: 57573 | E47: OMC | F47: 1087421900 | G47: Estefani Marilin Vallejo Ascuntar | H47: 100145829 | I47: 202604 | J47: 1087421900 | K47: OPCION DE GRADO | L47: CURSO MOD GRADO GERE SEGUR VIR | M47: EDUCACION CONTINUA | N47: CEI_BOGOTA | O47: Estudiante Nuevo | P47: Contact | Q47: Sello Financiero | R47: Tiene Sello Financiero (Aprobado Directo) | S47: Cohorte 1 | T47: 60345453 | U47: JAVIER ORLANDO HERNANDEZ RIVERA | V47: OP GRADO - INGLÉS | W47: =IF(V47="pregrado",31, IF(V47="posgrados",31, IF(V47="rEINTEGROS",7, IF(V47="BIT",90, IF(V47="OP GRADO - INGLÉS",17,""))))) -> 17 | X47: Claudia Restrepo Gonzalez
A48: 46007.585 | B48: 20107858 | C48: ROMBO V2 | D48: 57580 | E48: OMC | F48: 1002417760 | G48: Caren Yulied Sichaca Carebuena | H48: 100154156 | I48: 202604 | J48: 1002417760 | K48: OPCION DE GRADO | L48: DIP SEG Y SALUD TRA RIES P VIR | M48: EDUCACION CONTINUA | N48: CEI_BOGOTA | O48: Estudiante Nuevo | P48: Contact | Q48: Sello Financiero | R48: Tiene Sello Financiero (Aprobado Directo) | S48: Cohorte 1 | T48: 52834109 | U48: JAVIER ORLANDO HERNANDEZ RIVERA | V48: OP GRADO - INGLÉS | W48: =IF(V48="pregrado",31, IF(V48="posgrados",31, IF(V48="rEINTEGROS",7, IF(V48="BIT",90, IF(V48="OP GRADO - INGLÉS",17,""))))) -> 17 | X48: Jeny Marlen Ordoñez Mendez
A49: 46031.721 | B49: 20112180 | C49: ROMBO V2 | D49: 57596 | E49: OMC | F49: 1016039358 | G49: Piedad Piedad Guzman Olaya | H49: 100159920 | I49: 202604 | J49: 1016039358 | K49: OPCION DE GRADO | L49: DIPLOMADO NIIF VIRTUAL | M49: EDUCACION CONTINUA | N49: CEI_BOGOTA | O49: Estudiante Nuevo | P49: Contact | Q49: Sello Financiero | R49: Tiene Sello Financiero (Aprobado Directo) | S49: Cohorte 1 | T49: 1033714104 | U49: JAVIER ORLANDO HERNANDEZ RIVERA | V49: OP GRADO - INGLÉS | W49: =IF(V49="pregrado",31, IF(V49="posgrados",31, IF(V49="rEINTEGROS",7, IF(V49="BIT",90, IF(V49="OP GRADO - INGLÉS",17,""))))) -> 17 | X49: Ruben Darío Elles Trujillo
A50: 46007.539 | B50: 20107837 | C50: ROMBO V2 | D50: 57597 | E50: OMC | F50: 1120566184 | G50: Juan Giovanni Fonseca Plazas | H50: 100159979 | I50: 202604 | J50: 1120566184 | K50: OPCION DE GRADO | L50: DIP SEG Y SALUD TRA RIES P VIR | M50: EDUCACION CONTINUA | N50: CEI_BOGOTA | O50: Estudiante Nuevo | P50: Contact | Q50: Sello Financiero | R50: Tiene Sello Financiero (Aprobado Directo) | S50: Cohorte 1 | T50: 1033714104 | U50: JAVIER ORLANDO HERNANDEZ RIVERA | V50: OP GRADO - INGLÉS | W50: =IF(V50="pregrado",31, IF(V50="posgrados",31, IF(V50="rEINTEGROS",7, IF(V50="BIT",90, IF(V50="OP GRADO - INGLÉS",17,""))))) -> 17 | X50: Ruben Darío Elles Trujillo
A51: 46014.463 | B51: 20109450 | C51: ROMBO V2 | D51: 57602 | E51: OMC | F51: 20767709 | G51: Ana Orfilia Ordoñez Castro | H51: 100163216 | I51: 202604 | J51: 1025520781 | K51: OPCION DE GRADO | L51: CURSO MOD GRAD GER FINANC VIRT | M51: EDUCACION CONTINUA | N51: CEI_BOGOTA | O51: Estudiante Nuevo | P51: Contact | Q51: Sello Financiero | R51: Tiene Sello Financiero (Aprobado Directo) | S51: Cohorte 1 | T51: 1033714104 | U51: JAVIER ORLANDO HERNANDEZ RIVERA | V51: OP GRADO - INGLÉS | W51: =IF(V51="pregrado",31, IF(V51="posgrados",31, IF(V51="rEINTEGROS",7, IF(V51="BIT",90, IF(V51="OP GRADO - INGLÉS",17,""))))) -> 17 | X51: Ruben Darío Elles Trujillo
A52: 46011.777 | B52: 20109039 | C52: ROMBO V2 | D52: 57608 | E52: OMC | F52: 39739184 | G52: Maria Elena Ramos Cañon | H52: 100165931 | I52: 202604 | J52: 1019090252 | K52: OPCION DE GRADO | L52: CUR MOD GR ESP GES SAL PÚB VIR | M52: EDUCACION CONTINUA | N52: SENA CONVENIO NACIONAL | O52: Estudiante Nuevo | P52: Contact | Q52: Sello Financiero | R52: Tiene Sello Financiero (Aprobado Directo) | S52: Cohorte 1 | T52: 1033714104 | U52: JAVIER ORLANDO HERNANDEZ RIVERA | V52: OP GRADO - INGLÉS | W52: =IF(V52="pregrado",31, IF(V52="posgrados",31, IF(V52="rEINTEGROS",7, IF(V52="BIT",90, IF(V52="OP GRADO - INGLÉS",17,""))))) -> 17 | X52: Ruben Darío Elles Trujillo
... A133: 46051.648 | B133: 20118577 | C133: ROMBO V2 | D133: 60542 | E133: OMC | F133: 1000753058 | G133: Karen Liset Londoño Villada | H133: 100241734 | I133: 202604 | J133: 1000753058 | K133: PRIMER INGRESO | L133: BOOT PRIME PASOS MARKT DIG VIR | M133: EDUCACION CONTINUA | N133: CEI_BOGOTA | O133: Estudiante Nuevo | P133: Contact | Q133: Sello Financiero | R133: Tiene Sello Financiero (Aprobado Directo) | S133: Cohorte 1 | T133: 52221286 | U133: JOHAN SEBASTIAN PARDEYN AGUILAR | V133: BIT | W133: =IF(V133="pregrado",31, IF(V133="posgrados",31, IF(V133="rEINTEGROS",7, IF(V133="BIT",90, IF(V133="OP GRADO - INGLÉS",17,""))))) -> 90 | X133: Luz Yannet Gil Duran
A134: 46052.889 | B134: 20119182 | C134: ROMBO V2 | D134: 60546 | E134: OMC | F134: 1027523134 | G134: Jean Carlos Porras Orjuela | H134: 100099593 | I134: 202604 | J134: 1014656833 | K134: OPCION DE GRADO | L134: DIP SEG Y SALUD TRA RIES P VIR | M134: EDUCACION CONTINUA | N134: 0 | O134: Estudiante Nuevo | P134: Contact | Q134: Sello Financiero | R134: Tiene Sello Financiero (Aprobado Directo) | S134: Cohorte 1 | T134: 60345453 | U134: JAVIER ORLANDO HERNANDEZ RIVERA | V134: OP GRADO - INGLÉS | W134: =IF(V134="pregrado",31, IF(V134="posgrados",31, IF(V134="rEINTEGROS",7, IF(V134="BIT",90, IF(V134="OP GRADO - INGLÉS",17,""))))) -> 17 | X134: Claudia Restrepo Gonzalez
A135: 46069.604 | B135: 20123718 | C135: ROMBO V2 | D135: 60548 | E135: OMC | F135: 1033428371 | G135: Cesar Andres Carmona Marin | H135: 100158362 | I135: 202604 | J135: 1033428371 | K135: OPCION DE GRADO | L135: DIP SEG Y SALUD TRA RIES P VIR | M135: EDUCACION CONTINUA | N135: CEI_BOGOTA | O135: Estudiante Nuevo | P135: Contact | Q135: Sello Financiero | R135: Tiene Sello Financiero (Aprobado Directo) | S135: Cohorte 1 | T135: 1033714104 | U135: JAVIER ORLANDO HERNANDEZ RIVERA | V135: OP GRADO - INGLÉS | W135: =IF(V135="pregrado",31, IF(V135="posgrados",31, IF(V135="rEINTEGROS",7, IF(V135="BIT",90, IF(V135="OP GRADO - INGLÉS",17,""))))) -> 17 | X135: Ruben Darío Elles Trujillo
A136: 46037.417 | B136: 20113456 | C136: ROMBO V2 | D136: 60551 | E136: OMC | F136: 55245002 | G136: Sunamary Suna Torregrosa Hernandez | H136: 100219793 | I136: 202604 | J136: 55245002 | K136: OPCION DE GRADO | L136: SEM AUDIT INTER ISO 45001:2018 | M136: EDUCACION CONTINUA | N136: CEI_BOGOTA | O136: Estudiante Nuevo | P136: Contact | Q136: Sello Financiero | R136: Tiene Sello Financiero (Aprobado Directo) | S136: Cohorte 1 | T136: 1033714104 | U136: JAVIER ORLANDO HERNANDEZ RIVERA | V136: OP GRADO - INGLÉS | W136: =IF(V136="pregrado",31, IF(V136="posgrados",31, IF(V136="rEINTEGROS",7, IF(V136="BIT",90, IF(V136="OP GRADO - INGLÉS",17,""))))) -> 17 | X136: Ruben Darío Elles Trujillo
A137: 46042.68 | B137: 20115426 | C137: ROMBO V2 | D137: 60554 | E137: OMC | F137: 1043414056 | G137: Juan Pablo Zapata Jaramillo jaramillo | H137: 100129865 | I137: 202604 | J137: 1043414056 | K137: OPCION DE GRADO | L137: DIPL OPC GRADO DESLLO WEB VIR | M137: EDUCACION CONTINUA | N137: CEI_BOGOTA | O137: Estudiante Nuevo | P137: Contact | Q137: Sello Financiero | R137: Tiene Sello Financiero (Aprobado Directo) | S137: Cohorte 1 | T137: 1033714104 | U137: JAVIER ORLANDO HERNANDEZ RIVERA | V137: OP GRADO - INGLÉS | W137: =IF(V137="pregrado",31, IF(V137="posgrados",31, IF(V137="rEINTEGROS",7, IF(V137="BIT",90, IF(V137="OP GRADO - INGLÉS",17,""))))) -> 17 | X137: Ruben Darío Elles Trujillo
A138: 46038.466 | B138: 20114151 | C138: ROMBO V2 | D138: 60562 | E138: OMC | F138: 52884494 | G138: Andrea Jaqueline Gallo Neuta | H138: 900008121 | I138: 202604 | J138: 52884494 | K138: OPCION DE GRADO | L138: DIP SEG Y SALUD TRA RIES P VIR | M138: EDUCACION CONTINUA | N138: CEI_BOGOTA | O138: Estudiante Nuevo | P138: Contact | Q138: Sello Financiero | R138: Tiene Sello Financiero (Aprobado Directo) | S138: Cohorte 1 | T138: 52834109 | U138: JAVIER ORLANDO HERNANDEZ RIVERA | V138: OP GRADO - INGLÉS | W138: =IF(V138="pregrado",31, IF(V138="posgrados",31, IF(V138="rEINTEGROS",7, IF(V138="BIT",90, IF(V138="OP GRADO - INGLÉS",17,""))))) -> 17 | X138: Jeny Marlen Ordoñez Mendez
A139: 46052.526 | B139: 20118921 | C139: ROMBO V2 | D139: 60570 | E139: OMC | F139: 1002605086 | G139: Yesly Daniela Lopez Tejedor | H139: 100137594 | I139: 202604 | J139: 1002605086 | K139: PRIMER INGRESO | L139: BOOTCAMP DATA SCIENCE VIRT | M139: EDUCACION CONTINUA | N139: CEI_BOGOTA | O139: Estudiante Nuevo | P139: Contact | Q139: Sello Financiero | R139: Tiene Sello Financiero (Aprobado Directo) | S139: Cohorte 1 | T139: 52221286 | U139: JOHAN SEBASTIAN PARDEYN AGUILAR | V139: BIT | W139: =IF(V139="pregrado",31, IF(V139="posgrados",31, IF(V139="rEINTEGROS",7, IF(V139="BIT",90, IF(V139="OP GRADO - INGLÉS",17,""))))) -> 90 | X139: Luz Yannet Gil Duran
A140: 46038.717 | B140: 20114514 | C140: ROMBO V2 | D140: 60591 | E140: OMC | F140: 1113651654 | G140: María Camila Giraldo Gomez | H140: 100242000 | I140: 202604 | J140: 1114243695 | K140: PRIMER INGRESO | L140: BOOT PRIME PASOS MARKT DIG VIR | M140: EDUCACION CONTINUA | N140: CEI_BOGOTA | O140: Estudiante Nuevo | P140: Contact | Q140: Sello Financiero | R140: Tiene Sello Financiero (Aprobado Directo) | S140: Cohorte 1 | T140: 1018484247 | U140: JOHAN SEBASTIAN PARDEYN AGUILAR | V140: BIT | W140: =IF(V140="pregrado",31, IF(V140="posgrados",31, IF(V140="rEINTEGROS",7, IF(V140="BIT",90, IF(V140="OP GRADO - INGLÉS",17,""))))) -> 90 | X140: Sebastián Harvey Castillo Rodríguez
A141: 46038.702 | B141: 20114495 | C141: ROMBO V2 | D141: 60594 | E141: OMC | F141: 31016471 | G141: Rocio Sanchez Ariza | H141: 100219814 | I141: 202604 | J141: 1123038644 | K141: OPCION DE GRADO | L141: SEM COMPORT APREND Y CAMB ORGA | M141: EDUCACION CONTINUA | N141: CEI_BOGOTA | O141: Estudiante Nuevo | P141: Contact | Q141: Sello Financiero | R141: Tiene Sello Financiero (Aprobado Directo) | S141: Cohorte 1 | T141: 1033714104 | U141: JAVIER ORLANDO HERNANDEZ RIVERA | V141: OP GRADO - INGLÉS | W141: =IF(V141="pregrado",31, IF(V141="posgrados",31, IF(V141="rEINTEGROS",7, IF(V141="BIT",90, IF(V141="OP GRADO - INGLÉS",17,""))))) -> 17 | X141: Ruben Darío Elles Trujillo
A142: 46038.509 | B142: 20114214 | C142: ROMBO V2 | D142: 60606 | E142: OMC | F142: 64563726 | G142: LUZ HELENA CASTRO MADERA | H142: 100242071 | I142: 202604 | J142: 1044604657 | K142: PRIMER INGRESO | L142: BOOT DES WEB FUL STACK 400 ONL | M142: EDUCACION CONTINUA | N142: CEI_BOGOTA | O142: Estudiante Nuevo | P142: Contact | Q142: Sello Financiero | R142: Tiene Sello Financiero (Aprobado Directo) | S142: Cohorte 1 | T142: 1019052150 | U142: JOHAN SEBASTIAN PARDEYN AGUILAR | V142: BIT | W142: =IF(V142="pregrado",31, IF(V142="posgrados",31, IF(V142="rEINTEGROS",7, IF(V142="BIT",90, IF(V142="OP GRADO - INGLÉS",17,""))))) -> 90 | X142: Helmuth Stiven Navas Landazuri
A143: 46052.732 | B143: 20119136 | C143: ROMBO V2 | D143: 60618 | E143: OMC | F143: 72203630 | G143: armando beleño bolaño | H143: 100121144 | I143: 202604 | J143: 1064114548 | K143: OPCION DE GRADO | L143: DIPLOMADO TELEPSICOLOGIA VIR | M143: EDUCACION CONTINUA | N143: CEI_BOGOTA | O143: Estudiante Nuevo | P143: Contact | Q143: Sello Financiero | R143: Tiene Sello Financiero (Aprobado Directo) | S143: Cohorte 1 | T143: 1033714104 | U143: JAVIER ORLANDO HERNANDEZ RIVERA | V143: OP GRADO - INGLÉS | W143: =IF(V143="pregrado",31, IF(V143="posgrados",31, IF(V143="rEINTEGROS",7, IF(V143="BIT",90, IF(V143="OP GRADO - INGLÉS",17,""))))) -> 17 | X143: Ruben Darío Elles Trujillo
A144: 46038.654 | B144: 20114409 | C144: ROMBO V2 | D144: 60622 | E144: OMC | F144: 1001593631 | G144: Yessenia Yessenia Urango Vargas | H144: 100242144 | I144: 202604 | J144: 1001593631 | K144: PRIMER INGRESO | L144: BOOTCAMP DATA SCIENCE VIRT | M144: EDUCACION CONTINUA | N144: CEI_BOGOTA | O144: Estudiante Nuevo | P144: Contact | Q144: Sello Financiero | R144: Tiene Sello Financiero (Aprobado Directo) | S144: Cohorte 1 | T144: 1000788047 | U144: JOHAN SEBASTIAN PARDEYN AGUILAR | V144: BIT | W144: =IF(V144="pregrado",31, IF(V144="posgrados",31, IF(V144="rEINTEGROS",7, IF(V144="BIT",90, IF(V144="OP GRADO - INGLÉS",17,""))))) -> 90 | X144: Lizeth Helena Puerto Pinto
A145: 46055.629 | B145: 20119707 | C145: ROMBO V2 | D145: 60627 | E145: OMC | F145: 38684244 | G145: Derly Yohana Rivas Caicedo | H145: 100195506 | I145: 202604 | J145: 1006101870 | K145: OPCION DE GRADO | L145: CUR MOD GR ESP INTEL ARTIF VIR | M145: EDUCACION CONTINUA | N145: CEI_BOGOTA | O145: Estudiante Nuevo | P145: Contact | Q145: Sello Financiero | R145: Tiene Sello Financiero (Aprobado Directo) | S145: Cohorte 1 | T145: 1033714104 | U145: JAVIER ORLANDO HERNANDEZ RIVERA | V145: OP GRADO - INGLÉS | W145: =IF(V145="pregrado",31, IF(V145="posgrados",31, IF(V145="rEINTEGROS",7, IF(V145="BIT",90, IF(V145="OP GRADO - INGLÉS",17,""))))) -> 17 | X145: Ruben Darío Elles Trujillo
...

Sheet Hoja2
A1: cc | B1: Lider | C1: Area | D1: Asesor
A2: 39658730 | B2: MARSHIA MILENA JIMéNEZ GóMEZ | C2: PREGRADO | D2: Nelly Cuellar Rodriguez
A3: 39658730 | B3: MARSHIA MILENA JIMéNEZ GóMEZ | C3: PREGRADO | D3: Nelly Cuellar Rodriguez
A4: 39658730 | B4: MARSHIA MILENA JIMéNEZ GóMEZ | C4: PREGRADO | D4: Nelly Cuellar Rodriguez
A5: 39658730 | B5: MARSHIA MILENA JIMéNEZ GóMEZ | C5: PREGRADO | D5: Nelly Cuellar Rodriguez
A6: 39658730 | B6: MARSHIA MILENA JIMéNEZ GóMEZ | C6: PREGRADO | D6: Nelly Cuellar Rodriguez
A7: 39658730 | B7: MARSHIA MILENA JIMéNEZ GóMEZ | C7: PREGRADO | D7: Nelly Cuellar Rodriguez
A8: 39658730 | B8: MARSHIA MILENA JIMéNEZ GóMEZ | C8: PREGRADO | D8: Nelly Cuellar Rodriguez
A9: 39658730 | B9: MARSHIA MILENA JIMéNEZ GóMEZ | C9: PREGRADO | D9: Nelly Cuellar Rodriguez
A10: 39658730 | B10: MARSHIA MILENA JIMéNEZ GóMEZ | C10: PREGRADO | D10: Nelly Cuellar Rodriguez
A11: 39658730 | B11: MARSHIA MILENA JIMéNEZ GóMEZ | C11: PREGRADO | D11: Nelly Cuellar Rodriguez
A12: 39658730 | B12: MARSHIA MILENA JIMéNEZ GóMEZ | C12: PREGRADO | D12: Nelly Cuellar Rodriguez
A13: 39666517 | B13: PAOLA ANDREA CALDERON CETINA | C13: PREGRADO | D13: Consuelo Villada Ocampo
... A3813: 1033750951 | B3813: Johan Sebastián Pardeyn Aguilar | C3813: BIT | D3813: Yina Paola Baracaldo Reyes

Sheet Puntos
A1: Area | B1: Puntos piso 1
A3: pregados | B3: 30.754515
A4: posgrados | B4: 30.98721
A5: reingresos | B5: 7.1760534
A6: botcamps-bit | B6: 89.518605
A7: OP GRADO - INGLÉS | B7: 16.744125

Sheet Hoja3
A1: Asesor | B1: cc | C1: Lider | D1: area ( pregrDO POSGRADO(
A2: Cristian Camilo Caballero Reyes | F2: pregados
A3: Deivid Santiago Joya Apolin | F3: posgrados
A4: Esteban Camilo Mora Beltran | F4: reingresos
A5: Jaider Stiven Trujillo Cuellar | F5: botcamps-bit
A6: Jordy Adrian Muñoz | F6: OP GRADO - INGLÉS
A7: Julián Andrés Alejo Velasco
A8: Kelly Johana Porras Parra
A9: Laura Katerine Charry Avila
A10: Laura Tatiana Rodriguez
A11: Luisa fernanda cardozo salgado
A12: Maria Catalina Barahona Sabogal
A13: Maria Ines Cetina Cetina
A14: Paula Andrea Blanco Rojas
A15: Yina Paola Baracaldo Reyes
A19: [11:51 a. m., 19/5/2026] NATALY SARMIENTO: maslarga
A20: [11:54 a. m., 19/5/2026] Gina Ibero: ASESOR | B20: CC | C20: LIDER | D20: AREA
A21: Cristian Camilo Caballero Reyes | B21: 1023000285 | C21: Catalina Pacheco Burgos | D21: PREGRADO
A22: Deivid Santiago Joya Apolin | B22: 1032678391 | C22: Nelson Javier Morera Rincon | D22: PREGRADO
A23: Esteban Camilo Mora Beltran | B23: 1099215811 | C23: Heidy Lorena Prieto Ahumada | D23: PREGRADO
A24: Jaider Stiven Trujillo Cuellar | B24: 1006459732 | C24: Catalina Pacheco Burgos | D24: PREGRADO
A25: Jordy Adrian Muñoz | B25: 1000286877 | C25: Catalina Pacheco Burgos | D25: PREGRADO
A26: Julián Andrés Alejo Velasco | B26: 1018455773 | C26: Catalina Pacheco Burgos | D26: PREGRADO
A27: Kelly Johana Porras Parra | B27: 1013634750 | C27: OP NACIONAL | D27: PREGRADO
A28: Laura Katerine Charry Avila | B28: 1015407851 | C28: Gina Paola Medina Flórez | D28: PREGRADO
A29: Laura Tatiana Rodriguez | B29: 1000777598 | C29: Catalina Pacheco Burgos | D29: PREGRADO
A30: Luisa fernanda cardozo salgado | B30: 1030561016 | C30: JENIFFER VARGAS | D30: PREGRADO
A31: Maria Catalina Barahona Sabogal | B31: 52429528 | C31: JENIFFER VARGAS | D31: CALIDAD
A32: Maria Ines Cetina Cetina | B32: 1057582137 | C32: Paola Andrea Calderon Cetina | D32: PREGRADO
... A34: Yina Paola Baracaldo Reyes | B34: 1033750951 | C34: Johan Sebastián Pardeyn Aguilar | D34: BIT
